Workbook
Name Feed_list_merged_1: Complete_list!$F$1:$AF$345

Sheet Complete_list
A1: GLEAM_code | B1: Item_Name | C1: GLEAM3_name | D1: Category | E1: Data | F1: Item_code_CPC | G1: Source_Item_code_CPC | H1: Item_code_FAO | I1: Source_Item_code_FAO | J1: Description | K1: Cattle | L1: Sheep | M1: Goat | N1: Pigs | O1: Chicken | P1: Species | Q1: FAOSTAT domain | R1: cr_slope | S1: cr_intercept | T1: Dry matter content (%) | U1: GE (Mj/kgDM) | V1: DE_ruminats (Mj/kgDM) | W1: DE_pigs (Mj/kgDM) | X1: ME_ruminants (Mj/kgDM) | Y1: ME_pigs (Mj/kgDM) | Z1: ME_chickens (Mj/kgDM) | AA1: CP (% DM) | AB1: N_content (kg N / kg DM) | AC1: Nitrogen digestibility (%)ruminans | AD1: Nitrogen digestibility (%)pigs | AE1: Reference1 | AF1: Reference2 | AG1: Note
A2: F1 | B2: Fresh grass | C2: GRASSF | D2: Grass and leaves | E2: available | J2: Any type of natural or cultivated fresh grass grazed or fed to the animals. | K2: Y | L2: Y | M2: Y | N2: Y | O2: Y | P2: All | T2: =AVERAGE(T141,T152) -> 20.555 | U2: 18.7 | V2: =U2*68.4/100 -> 12.7908 | W2: =AVERAGE(7.1,8.7) -> 7.9 | X2: 10.7 | Y2: =AVERAGE(6.6,7.9) -> 7.25 | Z2: 5.65 | AA2: 16.2 | AB2: =AA2/6.25/100 -> 0.02592 | AC2: 71.3 | AD2: =AVERAGE(45.5,59.3) -> 52.4 | AE2: https://www.feedtables.com/content/grass-dehydrated
A3: F2 | B3: Wheat, straw | C3: WSTRAW | D3: Crop residues | E3: available | F3: 1913 | G3: 111 | H3: 635 | I3: 15 | J3: Fibrous residual plant material such as straw, brans, leaves, etc. from wheat (Triticum spp.) cultivation. | K3: Y | L3: Y | N3: Y | O3: Y | P3: Ruminants | Q3: Production | R3: 1.51 | S3: 0.52 | T3: 91 | U3: 18.5 | V3: 8.3 | W3: 2.3 | X3: 6.8 | Y3: 2 | AA3: 4.2 | AB3: 0.00672 | AC3: 3.5 | AE3: http://www.feedipedia.org/node/12758
A4: F3 | B4: Wheat | C4: WHEAT | D4: Cereals | E4: available | F4: 111 | G4: 111 | H4: 15 | I4: 15 | J4: Grains from wheat (Triticum aestivum). | K4: Y | M4: Y | N4: Y | O4: Y | P4: All | Q4: Production | T4: 87 | U4: 18.2 | V4: 15.6 | W4: 15.9 | X4: 13.1 | Y4: 15.5 | Z4: 14.1 | AA4: 12.6 | AB4: 0.02016 | AC4: 70.4 | AD4: 83.5 | AE4: https://www.feedipedia.org/node/223
A5: F4 | B5: Maize (corn), stover | C5: ZSTOVER | D5: Crop residues | E5: available | F5: 1913 | G5: 112 | H5: 635 | I5: 56 | J5: Fibrous residual plant material such as straw, brans, leaves, etc. from maize (Zea mays) cultivation. | K5: Y | L5: Y | N5: Y | O5: Y | P5: Ruminants | Q5: Production | R5: 1.03 | S5: 0.61 | T5: 61.2 | U5: 18.2 | V5: 9.4 | X5: 7.65 | AA5: 5.35 | AB5: 0.00856 | AC5: -37 | AE5: see sheet Maize stover)
A6: F5 | B6: Maize (corn) | C6: MAIZE | D6: Cereals | E6: available | F6: 112 | G6: 112 | H6: 56 | I6: 56 | J6: Grains from maize (Zea mays). | K6: Y | N6: Y | O6: Y | P6: All | Q6: Production | T6: 87.26 | U6: 18.716667 | V6: 16.1 | W6: 16.416667 | X6: 13.583333 | Y6: 16.033333 | Z6: 15.1375 | AA6: 9.1 | AB6: 0.01456 | AC6: 66 | AD6: 80.4 | AE6: see sheet Maize)
A7: F6 | B7: Rice, straw | C7: RSTRAW | D7: Crop residues | E7: available | F7: 1913 | G7: 113 | H7: 635 | I7: 27 | J7: Fibrous residual plant material such as straw, brans, leaves, etc. from rice (Oryza spp.) cultivation. | K7: Y | L7: Y | M7: Y | N7: Y | P7: Ruminants | Q7: Production | R7: 0.95 | S7: 2.46 | T7: 92.8 | U7: 15.5 | V7: 7.2 | W7: 5.4 | X7: 5.8 | AA7: 4.2 | AB7: 0.00672 | AC7: 2.1 | AE7: http://www.feedipedia.org/node/11646
A8: F7 | B8: Rice | C8: RICE | D8: Cereals | E8: available | F8: 113 | G8: 113 | H8: 27 | I8: 27 | J8: Grains from rice (Oryza spp.), polished | K8: Y | L8: Y | M8: Y | N8: Y | O8: Y | P8: All | Q8: Production | T8: 89.2 | U8: 18 | V8: 15.9 | W8: 17.1 | X8: 13.4 | Y8: 16.6 | Z8: =AVERAGE(15.9,15.6) -> 15.75 | AA8: 10.4 | AB8: =AA8/6.25/100 -> 0.01664 | AC8: 70 | AD8: 92 | AE8: https://www.feedipedia.org/node/12526
A9: F8 | B9: Sorghum, stover | C9: SSTOVER | D9: Crop residues | E9: available | F9: 1913 | G9: 114 | H9: 635 | I9: 83 | J9: Fibrous residual plant material such as straw, brans, leaves, etc. from sorghum (Sorghum spp.) cultivation. | K9: Y | L9: Y | M9: Y | P9: Ruminants | Q9: Production | R9: 0.88 | S9: 1.33 | T9: 93 | U9: 18.1 | V9: 8.9 | X9: 7.3 | AA9: 3.7 | AB9: 0.00592 | AC9: 30 | AE9: http://www.feedipedia.org/node/12618
A10: F9 | B10: Sorghum | C10: SORGHUM | D10: Cereals | E10: available | F10: 114 | G10: 114 | H10: 83 | I10: 83 | J10: Grains from sorghum (Sorghum spp.). | K10: Y | L10: Y | N10: Y | O10: Y | P10: All | Q10: Production | T10: 87.4 | U10: 18.8 | V10: 16 | W10: 16.1 | X10: 13.5 | Y10: 15.7 | Z10: 15.85 | AA10: 10.8 | AB10: 0.01728 | AC10: 68.4 | AD10: 70.6 | AE10: https://www.feedipedia.org/node/224
A11: F10 | B11: Barley, straw | C11: BSTRAW | D11: Crop residues | E11: available | F11: 1913 | G11: 115 | H11: 635 | I11: 44 | J11: Fibrous residual plant material such as straw, brans, leaves, etc. from barley (Hordeum vulgare), rye (Secale cereale) or oat (Avena sativa) cultivation. | K11: Y | L11: Y | N11: Y | O11: Y | P11: All | Q11: Production | R11: 0.98 | S11: 0.59 | T11: 90.9 | U11: 18.2 | V11: 8 | W11: 0.025 | X11: 6.5 | Y11: 2.2 | AA11: 3.8 | AB11: 0.00608 | AC11: 22.8 | AE11: https://www.feedipedia.org/node/11830
A12: F11 | B12: Barley | C12: BARLEY | D12: Cereals | E12: available | F12: 115 | G12: 115 | H12: 44 | I12: 44 | J12: Grains from barley (Hordeum vulgare). | K12: Y | L12: Y | M12: Y | N12: Y | O12: Y | P12: All | Q12: Production | T12: 87.1 | U12: 18.4 | V12: 14.8 | W12: 14.8 | X12: 12.4 | Y12: 14.3 | Z12: 12.25 | AA12: 11.8 | AB12: 0.01888 | AC12: 66.6 | AD12: 76.2 | AE12: https://www.feedipedia.org/node/227
A13: F12 | B13: Rye, straw | D13: Crop residues | E13: available | F13: 1913 | G13: 116 | H13: 635 | I13: 71 | J13: Fibrous residual plant material such as straw, brans, leaves, etc. from ryey (Secale cereale) cultivation. | K13: Y | L13: Y | N13: Y | O13: Y | P13: All | Q13: Production | R13: 1.09 | S13: 0.88 | T13: 92 | U13: 18.3 | V13: 8.2 | W13: 2.2 | X13: 6.6 | Y13: 1.9 | AA13: 4.1 | AB13: 0.00656 | AC13: 2 | AE13: https://www.feedipedia.org/node/14205
A14: F13 | B14: Rye | C14: GRAINS | D14: Cereals | E14: available | F14: 116 | G14: 116 | H14: 71 | I14: 71 | J14: Grains from rye (Secale cereale) | K14: Y | L14: Y | N14: Y | O14: Y | P14: Ruminants | Q14: Production | T14: 86.6 | U14: 18 | V14: 15.5 | W14: 15.1 | X14: 13 | Y14: 14.6 | Z14: 13.25 | AA14: 10.3 | AB14: 0.01648 | AC14: 68.3 | AD14: 70.9 | AE14: https://www.feedipedia.org/node/12542 | AG14: not used commonly as feed low protein low fibre not palatable
A15: F14 | B15: Oats, straw | D15: Crop residues | E15: available | F15: 1913 | G15: 117 | H15: 635 | I15: 75 | J15: Fibrous residual plant material such as straw, brans, leaves, etc. from oat (Avena sativa) cultivation. | K15: Y | L15: Y | N15: Y | O15: Y | P15: Ruminants | Q15: Production | R15: 0.91 | S15: 0.89 | T15: 89.6 | U15: 18 | V15: 8.1 | W15: 2.7 | X15: 6.6 | Y15: 2.4 | AA15: 3.6 | AB15: 0.00576 | AC15: 31 | AE15: https://www.feedipedia.org/node/12389
A16: F15 | B16: Oats | C16: GRAINS | D16: Cereals | E16: available | F16: 117 | G16: 117 | H16: 75 | I16: 75 | J16: Grains from oat (Avena sativa). | K16: Y | L16: Y | N16: Y | O16: Y | P16: All | Q16: Production | T16: 87.9 | U16: 19.5 | V16: 14.7 | W16: 12.7 | X16: 12.2 | Y16: 12.2 | Z16: 11.5 | AA16: 11 | AB16: 0.0176 | AC16: 63.9 | AD16: 75.9 | AE16: https://www.feedipedia.org/node/12391
A17: F16 | B17: Millet, stover | C17: MSTOVER | D17: Crop residues | E17: available | F17: 1913 | G17: 118 | H17: 635 | I17: 79 | J17: Fibrous residual plant material such as straw, brans, leaves, etc. from millet (Pennisetum glaucum, Eleusine coracana, Panicum miliaceum, etc) cultivation. | K17: Y | L17: Y | M17: Y | P17: Ruminants | Q17: Production | R17: 1.43 | S17: 0.14 | T17: 93.6 | U17: 17.725 | V17: 8.925 | X17: 7.225 | AA17: 4.375 | AB17: 0.007 | AC17: 10.3 | AE17: see sheet Millet stover)
A18: F17 | B18: Millet | C18: MILLET | D18: Cereals | E18: available | F18: 118 | G18: 118 | H18: 79 | I18: 79 | J18: Grains from millet (P. glaucum, E. coracana, P. miliaceum, and others). | P18: Monogastrics | Q18: Production | T18: 89.8 | U18: 18.725 | V18: 15.148933 | W18: 14.45 | X18: 12.633333 | Y18: 14.033333 | Z18: 14.333333 | AA18: 11.875 | AB18: 0.019 | AC18: 76.5 | AE18: see sheet Millet)
A19: F18 | B19: Triticale, straw | D19: Crop residues | E19: available, item missing from SUAS | F19: 1913 | G19: 1191 | H19: 635 | I19: 97 | J19: Straws from Triticale | K19: Y | N19: Y | O19: Y | R19: 1.09 | S19: 0.88 | T19: 92.5 | U19: 18.7 | V19: 8.8 | W19: 3 | X19: 7.2 | Y19: 2.7 | AA19: 3.2 | AB19: =AA19/6.25/100 -> 0.00512 | AE19: https://www.feedipedia.org/node/60
A20: F19 | B20: Triticale | D20: Cereals | E20: available | F20: 1191 | G20: 1191 | H20: 97 | I20: 97 | J20: Grains from Triticale | K20: Y | N20: Y | O20: Y | T20: 87.1 | U20: 18.1 | V20: 15.5 | W20: 15.6 | X20: 12.9 | Y20: 15.1 | Z20: 13.85 | AA20: 11.7 | AB20: =AA20/6.25/100 -> 0.01872 | AC20: 69.5 | AD20: 83.9 | AE20: https://www.feedipedia.org/node/6476 | AF20: Feedipedia page under costruction
A21: F20 | B21: Buckwheat, straw | D21: Crop residues | E21: available | F21: 1913 | G21: 1192 | H21: 635 | I21: 89 | J21: Fibrous residual plant material such as straw, brans, leaves, etc. from Buckwheat ((Fagopyrum esculentum) cultivation. | K21: Y | L21: Y | N21: Y | O21: Y | P21: Ruminants | Q21: Production | R21: 1.09 | S21: 0.88 | T21: 87.2 | U21: 18.7 | V21: 6.2 | X21: 4.9 | AA21: 4.6 | AB21: 0.00736 | AC21: 5.9 | AE21: https://www.feedipedia.org/node/25610
A22: F21 | B22: Buckwheat | C22: GRAINS | D22: Cereals | E22: available | F22: 1192 | G22: 1192 | H22: 89 | I22: 89 | J22: Grains from buckwheat (Fagopyrum esculentum). | K22: Y | L22: Y | N22: Y | O22: Y | P22: Ruminants | Q22: Production | T22: 84.9 | U22: 18.7 | V22: 11.6875 | W22: 12.3 | X22: 9.6 | Y22: 11.9 | AA22: 13.2 | AB22: 0.02112 | AC22: 58.3 | AD22: 70.7 | AE22: https://www.feedipedia.org/node/25140
A23: F22 | B23: Fonio, straw | D23: Crop residues | E23: available, item missing from SUAS | F23: 1913 | G23: 1193 | I23: 94 | J23: Fibrous residueal material such as straw, brans, leaves, etc, from Fonio (Digitaria exilis) | L23: Y | P23: Ruminants | R23: 1.09 | S23: 0.88 | T23: 94.1 | U23: 18.2 | X23: 7.2 | AA23: 5.6 | AB23: =AA23/6.25/100 -> 0.00896 | AC23: 60 | AE23: https://www.feedipedia.org/node/460
A24: F23 | B24: Fonio | D24: Cereals | E24: available | F24: 1193 | G24: 1193 | H24: 94 | I24: 94 | J24: Grains from Fonio (Digitaria exilis) | K24: Y | L24: Y | M24: Y | N24: Y | O24: Y | P24: All | T24: 89.1 | U24: 18.2 | W24: 13.5 | X24: 13.6 | Y24: 13.2 | Z24: =AVERAGE(13.1,13.3) -> 13.2 | AA24: 8.6 | AB24: =AA24/6.25/100 -> 0.01376 | AC24: 70.9 | AD24: 75.6 | AE24: https://www.feedipedia.org/node/228
A25: F24 | B25: Quinoa | D25: Cereals | E25: available | F25: 1194 | G25: 1194 | H25: 92 | I25: 92 | J25: Grain from Quinoa( Chenopodium quinoa) | L25: Y | M25: Y | N25: Y | O25: Y | P25: All | T25: 88.2 | U25: 19.1 | W25: 16.2 | X25: 13.7 | Y25: 15.7 | Z25: =AVERAGE(15.4,15.1) -> 15.25 | AA25: 13.6 | AB25: =AA25/6.25/100 -> 0.02176 | AC25: 71.5 | AD25: 82.5 | AE25: https://www.feedipedia.org/node/229
A26: F25 | B26: Quinoa, forage | D26: Fodder crop | E26: available, item missing from SUAS | G26: 1194 | I26: 92 | J26: Quinoa aerial part fresh | K26: Y | L26: Y | M26: Y | N26: Y | T26: 13.8 | U26: 15.4 | V26: 12.1 | X26: 9.5 | AA26: 18.8 | AB26: =AA26/6.25/100 -> 0.03008 | AE26: https://www.feedipedia.org/node/26044
A27: F26 | B27: Canary seed | D27: Other | E27: missing | F27: 1195 | AG27: Used as bird feed.
A28: F27 | B28: Mixed grain | C28: GRAINS | D28: Cereals | E28: available | F28: 1199.02 | H28: 103 | J28: Mixed grains is a mixture of cereal species that are sown and harvested together. It does not include meslin (a mixture wheat/rye) | P28: All | T28: =AVERAGE(T4,T6,T8,T10,T12,T14,T16,T18,T20,T22,T24,T25) -> 87.63 | U28: =AVERAGE(U4,U6,U8,U10,U12,U14,U16,U18,U20,U22,U24,U25) -> 18.536806 | V28: =AVERAGE(V4,V6,V8,V10,V12,V14,V16,V18,V20,V22,V24,V25) -> 15.093643 | W28: =AVERAGE(W4,W6,W8,W10,W12,W14,W16,W18,W20,W22,W24,W25) -> 15.013889 | X28: =AVERAGE(X4,X6,X8,X10,X12,X14,X16,X18,X20,X22,X24,X25) -> 12.801389 | Y28: =AVERAGE(Y4,Y6,Y8,Y10,Y12,Y14,Y16,Y18,Y20,Y22,Y24,Y25) -> 14.572222 | Z28: =AVERAGE(Z4,Z6,Z8,Z10,Z12,Z14,Z16,Z18,Z20,Z22,Z24,Z25) -> 14.042803 | AA28: =AVERAGE(AA4,AA6,AA8,AA10,AA12,AA14,AA16,AA18,AA20,AA22,AA24,AA25) -> 11.247917 | ... AD28: =AVERAGE(AD4,AD6,AD8,AD10,AD12,AD14,AD16,AD18,AD20,AD22,AD24,AD25) -> 78.381818 | AE28: average from Cereals
A29: F28 | B29: Other cereals n.e. | D29: Cereals | E29: available | F29: 1199.9 | H29: 108 | J29: This subclass includes among all: Chenopodium pallidicaule (canagua or coaihua), Amaranthus caudatus (quihuicha or Inca wheat), Coix lacryma-jobi (adlay or Job's tears), Zizania aquatica (wild rice) and other cereal crops and hybrid grains that are not identified separately because of their minor relevance at the international level. | P29: All | T29: =T28 -> 87.63 | U29: =U28 -> 18.536806 | V29: =V28 -> 15.093643 | W29: =W28 -> 15.013889 | X29: =X28 -> 12.801389 | Y29: =Y28 -> 14.572222 | Z29: =Z28 -> 14.042803 | AA29: =AA28 -> 11.247917 | ... AD29: =AD28 -> 78.381818 | AE29: average from Cereals
A30: F29 | B30: Cabbages | D30: Fruits and vegetables | E30: available | F30: 1212 | G30: 1212 | H30: 358 | I30: 358 | J30: Rape forage, fresh (Brassica sp) | Q30: Trade | T30: 12.1 | U30: 17.4 | V30: 13.2 | X30: 10.6 | AA30: 19.3 | AB30: =AA30/6.25/100 -> 0.03088 | AC30: 88.5 | AE30: https://www.feedipedia.org/node/15685
A31: F30 | B31: Cauliflowers and broccoli | D31: Fruits and vegetables | E31: missing | F31: 1213
A32: F31 | B32: Lettuce and chicory | D32: Fruits and vegetables | E32: missing | F32: 1214
A33: F32 | B33: Watermelons | D33: Fruits and vegetables | E33: available | F33: 1221 | G33: 1221 | H33: 567 | I33: 567 | J33: Fruit fresh (Citrullus lanatus) | K33: Y | N33: Y | Q33: Trade | T33: 7.9 | U33: 19.5 | W33: 9.4 | AA33: 10 | AB33: =AA33/6.25/100 -> 0.016 | AE33: https://www.feedipedia.org/node/166 | AF33: Feedipedia page under costruction
A34: F33 | B34: Cantaloupes and other melons | D34: Fruits and vegetables | E34: available | F34: 1229 | G34: 1229 | H34: 568 | I34: 568 | J34: Fruit fresh (Cucumis melo) | K34: Y | N34: Y | Q34: Trade | T34: 8.2 | U34: 17.5 | W34: 9 | X34: 8.3 | AA34: 17.7 | AB34: =AA34/6.25/100 -> 0.02832 | AE34: https://www.feedipedia.org/node/12325 | AF34: Feedipedia page under costruction
A35: F34 | B35: Cucumbers and gherkins | D35: Fruits and vegetables | E35: missing | F35: 1232
A36: F35 | B36: Eggplants (aubergines) | D36: Fruits and vegetables | E36: missing | F36: 1233
A37: F36 | B37: Tomatoes | D37: Fruits and vegetables | E37: available | F37: 1234 | G37: 1234 | H37: 388 | I37: 388 | J37: Fruit fresh | K37: Y | L37: Y | M37: Y | N37: Y | O37: Y | P37: All | Q37: Trade | T37: 7.3 | AE37: https://www.feedipedia.org/node/7791
A38: F37 | B38: Tomato pomace | D38: Other | E38: available, item missing from SUAS | G38: 1234 | I38: 388 | J38: Tomato pomace, tomato skins and tomato seeds | K38: Y | L38: Y | M38: Y | N38: Y | O38: Y | P38: All | T38: 93.5 | U38: 21.8 | V38: 12 | W38: 7.6 | X38: 9.3 | Y38: 6.8 | AA38: 21 | AB38: =AA38/6.25/100 -> 0.0336 | AC38: 65.4 | AE38: https://www.feedipedia.org/node/12705
A39: F38 | B39: Pumpkins, squash and gourds | D39: Fruits and vegetables | E39: available | F39: 1235 | G39: 1235 | H39: 394 | I39: 394 | J39: Pumpkins fresh, seeds, oil, hulls | K39: Y | N39: Y | Q39: Trade | T39: 70.6 | U39: 22.8 | X39: 11.9 | AA39: 31 | AB39: =AA39/6.25/100 -> 0.0496 | AC39: 70.3 | AE39: see sheet Pumpkin
A40: F39 | B40: Okra | D40: Fruits and vegetables | E40: available | F40: 1239.01 | G40: 1239.01 | H40: 430 | I40: 430 | J40: Okra (Abelmoschus esculentus) fruits, seeds, oil, fresh | Q40: Trade | T40: 52.7 | U40: 19.4 | W40: 10.7 | AA40: 19.6 | AB40: =AA40/6.25/100 -> 0.03136 | AE40: see sheet Okra
...

Sheet Change_LOG
A1: Date (MM/DD/YY) | B1: Change
A2: 45600 | B2: Added "Change_LOG".
A3: 45600 | B3: GLEAM3 name "RAPESEED" added to item F81 (Rapeseed or colza seed)
A4: 45600 | B4: GLEAM3 name "SOYOIL" was corrected to "SOY OIL".
A5: 45661 | B5: Data on milk nutritional values by species added to the database, including pig milk. To be used for the juvenile cohort.

Sheet Milk_composition
A1: Species | B1: DM | C1: GE_MJ/kgDM | D1: ME_ruminants | E1: ME_pigs | F1: DE_ruminants | G1: DE_pigs | H1: N_content (% per DM) | I1: Source
A2: Cattle | B2: =100-87.8 -> 12.2 | C2: =(64*0.004184)/B2*1000 -> 21.948852 | D2: =F2*96% -> 20.438771 | F2: =C2*97% -> 21.290387 | H2: =(3.2/B2%)/6.38 -> 4.1112082 | I2: Nayak, C., C. T. Ramachandra, and G. Kumar. "A Comprehensive Review on Composition of Donkey Milk in Comparison to Human, Cow, Buffalo, Sheep, Goat, Camel and Horse Milk." Mysore Journal of Agricultural Sciences 54, no. 3 (2020). | GE=value in kcal*conversion factor from kcal to MJ of 0.004184 | From GE to DE=0.97; From DE to ME=0.96 (Calculated from National Research Council, Committee on Animal Nutrition, & Subcommittee on Dairy Cattle Nutrition. (2001). Nutrient requirements of dairy cattle: 2001. National Academies Press.)
A3: Buffalo | B3: =100-82.4 -> 17.6 | C3: =(102.3*0.004184)/B3*1000 -> 24.3195 | D3: =F3*96% -> 22.646318 | F3: =C3*97% -> 23.589915 | H3: =(5/B3%)/6.38 -> 4.4528356 | I3: Nayak, C., C. T. Ramachandra, and G. Kumar. "A Comprehensive Review on Composition of Donkey Milk in Comparison to Human, Cow, Buffalo, Sheep, Goat, Camel and Horse Milk." Mysore Journal of Agricultural Sciences 54, no. 3 (2020). | GE=value in kcal*conversion factor from kcal to MJ of 0.004184 | From GE to DE=0.97; From DE to ME=0.96 (Calculated from National Research Council, Committee on Animal Nutrition, & Subcommittee on Dairy Cattle Nutrition. (2001). Nutrient requirements of dairy cattle: 2001. National Academies Press.)
A4: Sheep | B4: =100-81.6 -> 18.4 | C4: =(89.8*0.004184)/B4*1000 -> 20.419739 | D4: =F4*96% -> 19.014861 | F4: =C4*97% -> 19.807147 | H4: =(5.7/B4%)/6.38 -> 4.8555268 | I4: Nayak, C., C. T. Ramachandra, and G. Kumar. "A Comprehensive Review on Composition of Donkey Milk in Comparison to Human, Cow, Buffalo, Sheep, Goat, Camel and Horse Milk." Mysore Journal of Agricultural Sciences 54, no. 3 (2020). | GE=value in kcal*conversion factor from kcal to MJ of 0.004184 | From GE to DE=0.97; From DE to ME=0.96 (Calculated from National Research Council, Committee on Animal Nutrition, & Subcommittee on Dairy Cattle Nutrition. (2001). Nutrient requirements of dairy cattle: 2001. National Academies Press.)
A5: Goats | B5: =100-87.8 -> 12.2 | C5: =(64*0.004184)/B5*1000 -> 21.948852 | D5: =F5*96% -> 20.438771 | F5: =C5*97% -> 21.290387 | H5: =(3.2/B5%)/6.38 -> 4.1112082 | I5: Nayak, C., C. T. Ramachandra, and G. Kumar. "A Comprehensive Review on Composition of Donkey Milk in Comparison to Human, Cow, Buffalo, Sheep, Goat, Camel and Horse Milk." Mysore Journal of Agricultural Sciences 54, no. 3 (2020). | GE=value in kcal*conversion factor from kcal to MJ of 0.004184 | From GE to DE=0.97; From DE to ME=0.96 (Calculated from National Research Council, Committee on Animal Nutrition, & Subcommittee on Dairy Cattle Nutrition. (2001). Nutrient requirements of dairy cattle: 2001. National Academies Press.)
A6: Camels | B6: =100-88.44 -> 11.56 | C6: =(61.4*0.004184)/B6*1000 -> 22.222976 | D6: =F6*96% -> 20.694035 | F6: =C6*97% -> 21.556287 | H6: =(2.95/B6%)/6.38 -> 3.9998481 | I6: Nayak, C., C. T. Ramachandra, and G. Kumar. "A Comprehensive Review on Composition of Donkey Milk in Comparison to Human, Cow, Buffalo, Sheep, Goat, Camel and Horse Milk." Mysore Journal of Agricultural Sciences 54, no. 3 (2020). | GE=value in kcal*conversion factor from kcal to MJ of 0.004184 | From GE to DE=0.97; From DE to ME=0.96 (Calculated from National Research Council, Committee on Animal Nutrition, & Subcommittee on Dairy Cattle Nutrition. (2001). Nutrient requirements of dairy cattle: 2001. National Academies Press.)
A7: Pigs | B7: 17.9 | C7: =4.626/B7% -> 25.843575 | E7: =G7*96% -> 24.065537 | G7: =C7*97% -> 25.068268 | H7: =(5.34/B7%)/6.38 -> 4.6759251 | I7: Aguinaga, M. A., F. Gómez-Carballar, R. Nieto, and J. F. Aguilera. "Production and composition of Iberian sow's milk and use of milk nutrients by the suckling Iberian piglet." Animal 5, no. 9 (2011): 1390-1397. (assuming 97% from GE to DE, and 96% from DE to ME)
I8: 6.38 Nitrogen content. Source: National Academies of Sciences, Engineering, and Medicine; Division on Earth and Life Studies; Board on Agriculture and Natural Resources; Committee on Nutrient Requirements of Dairy Cattle. Nutrient Requirements of Dairy Cattle: Eighth Revised Edition. Washington (DC): National Academies Press (US); 2021 Aug 30. 3, Energy. Available from: https://www.ncbi.nlm.nih.gov/books/NBK600598/

Sheet Sunflower meal
A1: LEMON and LIME
D2: ruminants | G2: monogastrics
A3: Name | B3: Dry matter (%) | C3: GE (MJ/kg) | D3: DE (MJ/kg) | E3: ME (MJ/kg) | F3: Nitrogen digestibility (%) | G3: DE (MJ/kg) - pigs | H3: ME (MJ/kg) - pigs | I3: ME (MJ/kg) - poultry | J3: Nitrogen digestibility(%) | K3: CP (%DM) | L3: source
A4: Sunflower meal, solvent-extracted, dehulled or non-dehulled | B4: 89 | C4: 19.4 | D4: 11.8 | E4: 9.1 | F4: 84.5 | G4: 10.3 | H4: 9.4 | I4: 8.6 | J4: 78.4 | K4: 32.4 | L4: https://www.feedipedia.org/node/12663
A5: Sunflower meal, solvent-extracted, dehulled and partially dehulled | B5: 89.8 | C5: 19.3 | D5: 12.7 | E5: 9.6 | F5: 87.7 | G5: 11.6 | H5: 10.6 | I5: 8.8 | J5: 81.2 | K5: 37.7 | L5: https://www.feedipedia.org/node/12806
A6: Sunflower meal, solvent-extracted, non-dehulled | B6: 88.9 | C6: 19.4 | D6: 11.7 | E6: 8.9 | F6: 51.9 | G6: 10.1 | H6: 9.2 | I6: 6.2 | J6: 73.3 | K6: 31.3 | L6: https://www.feedipedia.org/node/12665
A7: Sunflower meal, mechanically-extracted | B7: 91.8 | C7: 21.8 | D7: 14 | E7: 10.9 | F7: 75 | G7: 12.1 | H7: 11.1 | I7: 10.8 | J7: 78 | K7: 27.9 | L7: https://www.feedipedia.org/node/12664
A8: mean | B8: =AVERAGE(B4,B5,B6,B7) -> 89.875 | C8: =AVERAGE(C4,C5,C6,C7) -> 19.975 | D8: =AVERAGE(D4,D5,D6,D7) -> 12.55 | E8: =AVERAGE(E5,E4,E6,E7) -> 9.625 | F8: =AVERAGE(F4,F5,F6,F7) -> 74.775 | G8: =AVERAGE(G4,G5,G6,G7) -> 11.025 | H8: =AVERAGE(H5,H4,H6,H7) -> 10.075 | I8: =AVERAGE(I4,I5,I6,I7) -> 8.6 | J8: =AVERAGE(J4,J5,J6,J7) -> 77.725 | K8: =AVERAGE(K4,K5,K6,K7) -> 32.325

Sheet Pumpkin
A1: PUMPKIN
D2: ruminants | G2: monogastrics
A3: Name | B3: Dry matter (%) | C3: GE (MJ/kg) | D3: DE (MJ/kg) | E3: ME (MJ/kg) | F3: Nitrogen digestibility | G3: DE (MJ/kg) | H3: ME (MJ/kg) - pigs | I3: ME (MJ/kg) - poultry | J3: CP (%DM)
A4: Pumpkin (Cucurbita sp.), fruits, fresh | B4: 7.6 | C4: 17.8 | E4: 13.6 | F4: 90 | G4: 12.4 | J4: 14.5 | K4: https://www.feedipedia.org/node/12480
A5: Pumpkin (Cucurbita sp.), fruit, dried | B5: 90.3 | C5: 18.8 | F5: 58.5 | J5: 9.4 | K5: https://www.feedipedia.org/node/14541
A6: Pumpkin (Cucurbita sp.), crop by-product, fresh | B6: 14 | J6: 19.8 | K6: https://www.feedipedia.org/node/14542
A7: Pumpkin (Cucurbita sp.), hulls | B7: 89.8 | C7: 22.1 | E7: 4.2 | F7: 38 | J7: 19 | K7: https://www.feedipedia.org/node/12481
A8: Pumpkin (Cucurbita sp.), oil meal, solvent extraction | B8: 92.2 | C8: 21 | E8: 10.5 | F8: 81 | G8: 7.7 | J8: 59.6 | K8: https://www.feedipedia.org/node/12483
A9: Pumpkin (Cucurbita sp.), oil meal, mechanical extraction | B9: 88 | C9: 22.6 | G9: 18.4 | J9: 63.2 | K9: https://www.feedipedia.org/node/12482
A10: Pumpkin (Cucurbita sp.), seeds with hulls | B10: 90 | C10: 27.8 | J10: 31.6 | K10: https://www.feedipedia.org/node/12485
A11: Pumpkin (Cucurbita sp.), seeds without hulls | B11: 92.6 | C11: 29.8 | E11: 19.3 | F11: 84 | J11: 35.7 | K11: https://www.feedipedia.org/node/12486
A13: mean | B13: =AVERAGE(B4,B5,B6,B7,B8,B9,B10,B11) -> 70.5625 | C13: =AVERAGE(C4,C5,C7,C8,C9,C10,C11) -> 22.842857 | E13: =AVERAGE(E4,E7,E8,E11) -> 11.9 | F13: =AVERAGE(F4,F5,F7,F8,F11) -> 70.3 | G13: =AVERAGE(G4,G8,G9) -> 12.833333 | J13: =AVERAGE(J4,J5,J6,J7,J8,J9,J10) -> 31.014286

Sheet Okra
A1: OKRA
D2: ruminants | G2: monogastrics
A3: Name | B3: Dry matter (%) | C3: GE (MJ/kg) | D3: DE (MJ/kg) | E3: ME (MJ/kg) | F3: Nitrogen digestibility | G3: DE (MJ/kg) | H3: ME (MJ/kg) - pigs | I3: ME (MJ/kg) - poultry | J3: CP (%DM)
A4: Okra (Abelmoschus esculentus), fruits, dry | B4: 87.5 | C4: 20.3 | G4: 6.5 | J4: 14.6 | K4: https://www.feedipedia.org/node/12400
A5: Okra (Abelmoschus esculentus), fruits, fresh | B5: 11.3 | C5: 16.8 | G5: 12.6 | J5: 15.8 | K5: https://www.feedipedia.org/node/12401
A6: Okra (Abelmoschus esculentus), leaves, fresh | B6: 18.5 | C6: 17.7 | J6: 23.8 | K6: https://www.feedipedia.org/node/12402
A7: Okra (Abelmoschus esculentus), oil cake | C7: 19.6 | G7: 11.6 | J7: 22.3 | K7: https://www.feedipedia.org/node/12403
A8: Okra (Abelmoschus esculentus), seeds | B8: 93.5 | C8: 22.7 | G8: 11.9 | J8: 21.3 | K8: https://www.feedipedia.org/node/12404
A13: mean | B13: =AVERAGE(B4,B5,B6,B7,B8,B9,B10,B11) -> 52.7 | C13: =AVERAGE(C4,C5,C6,C7,C8) -> 19.42 | E13: =AVERAGE(E4,E7,E8,E11) -> #DIV/0! | F13: =AVERAGE(F4,F5,F7,F8,F11) -> #DIV/0! | G13: =AVERAGE(G4,G5,G7,G8) -> 10.65 | J13: =AVERAGE(J4,J5,J6,J7,J8) -> 19.56

Sheet Fodder silage maize)
A1: MAIZE SILAGE
D2: ruminants | G2: monogastrics
A3: Name | C3: GE (MJ/kg) | D3: DE (MJ/kg) | E3: ME (MJ/kg) | G3: DE (MJ/kg) | H3: ME (MJ/kg) - pigs | I3: ME (MJ/kg) - poultry | J3: CP (%DM) | K3: source
A4: Maize silage, dry matter < 25% | B4: 23.5 | C4: 18.9 | D4: 12.8 | E4: 10.5 | F4: 54.9 | J4: 8 | K4: https://www.feedipedia.org/node/12869
A5: Maize silage, dry matter 25-30% | B5: 28.2 | C5: 19 | D5: 13.1 | E5: 10.8 | F5: 66.2 | J5: 7.2 | K5: https://www.feedipedia.org/node/12870
A6: Maize silage, dry matter 30-35% | B6: 32.5 | C6: 18.8 | D6: 13 | E6: 10.8 | F6: 54.6 | J6: 6.9 | K6: https://www.feedipedia.org/node/12871
A7: Maize silage, dry matter 35-40% | B7: 37 | C7: 19.1 | D7: 13.2 | E7: 11 | J7: 6.8 | K7: https://www.feedipedia.org/node/12872
A9: mean | B9: =AVERAGE(B4:B7) -> 30.3 | C9: =AVERAGE(C4:C7) -> 18.95 | D9: =AVERAGE(D4:D7) -> 13.025 | E9: =AVERAGE(E4:E7) -> 10.775 | F9: =AVERAGE(F4:F7) -> 58.566667 | G9: =AVERAGE(G4:G7) -> #DIV/0! | H9: =AVERAGE(H4:H7) -> #DIV/0! | I9: =AVERAGE(I4:I7) -> #DIV/0! | J9: =AVERAGE(J4:J7) -> 7.225

Sheet Maize stover)
A1: 12) ZSTOVER | C1: crop residue from maiZe
D2: ruminants | F2: monogastrics
A3: Name | B3: Dry metter content (%) | C3: GE (MJ/kg) | D3: DE (MJ/kg) | E3: ME (MJ/kg) | F3: DE (MJ/kg) | G3: ME (MJ/kg) - pigs | H3: ME (MJ/kg) - poultry | I3: CP (%DM) | J3: source
A4: Maize stover, fresh | B4: 29.6 | C4: 18.2 | D4: 10.3 | E4: 8.4 | F4: 56.7 | I4: 6.8 | J4: http://www.feedipedia.org/node/12873
A5: Maize stover, dried | B5: 92.8 | C5: 18.2 | D5: 8.5 | E5: 6.9 | F5: 46.8 | I5: 3.9 | J5: http://www.feedipedia.org/node/12874
A7: mean | B7: =AVERAGE(B4,B5) -> 61.2 | C7: =AVERAGE(C4:C5) -> 18.2 | D7: =AVERAGE(D4:D5) -> 9.4 | E7: =AVERAGE(E4:E5) -> 7.65 | F7: =AVERAGE(F4:F5) -> 51.75 | G7: =AVERAGE(G4:G5) -> #DIV/0! | H7: =AVERAGE(H4:H5) -> #DIV/0! | I7: =AVERAGE(I4:I5) -> 5.35

Sheet MIllet stover)
A1: 13) MSTOVER | C1: crop residue from Millet
C2: ruminants | G2: monogastrics
A3: Name | B3: Dry metter content (%) | C3: GE (MJ/kg) | D3: DE (MJ/kg) | E3: ME (MJ/kg) | F3: Nitrogen digestibility(%) | G3: DE (MJ/kg) - pigs | H3: ME (MJ/kg) - pigs | I3: ME (MJ/kg) - poultry | J3: CP (%DM) | K3: source
A4: Proso millet (Panicum miliaceum), straw | B4: 94.5 | C4: 17.7 | D4: 9 | E4: 7.2 | J4: 3.7 | K4: http://www.feedipedia.org/node/12009
A5: Finger millet (Eleusine coracana), straw, silage | C5: 17.8 | D5: 9.5 | E5: 7.7 | F5: 8 | J5: 3.6 | K5: http://www.feedipedia.org/node/12092
A6: Pearl millet (Pennisetum glaucum), straw | B6: 93.1 | C6: 17.7 | D6: 7.7 | E6: 6.3 | F6: 7 | J6: 5.2 | K6: http://www.feedipedia.org/node/12442
A7: Finger millet (Eleusine coracana), straw | B7: 93.1 | C7: 17.7 | D7: 9.5 | E7: 7.7 | F7: 16 | J7: 5 | K7: http://www.feedipedia.org/node/12091
A9: mean | B9: =AVERAGE(B4,B6,B7) -> 93.566667 | C9: =AVERAGE(C4:C7) -> 17.725 | D9: =AVERAGE(D4:D7) -> 8.925 | E9: =AVERAGE(E4:E7) -> 7.225 | F9: =AVERAGE(F5,F6,F7) -> 10.333333 | G9: =AVERAGE(G4:G7) -> #DIV/0! | H9: =AVERAGE(H4:H7) -> #DIV/0! | J9: =AVERAGE(J4:J7) -> 4.375

Sheet Pigeon peas straw)
A1: PIGEON PEAS STRAW | C1: crop residue from maiZe
D2: ruminants | G2: monogastrics
A3: Name | B3: Dry matter (%) | C3: GE (MJ/kg) | D3: DE (MJ/kg) | E3: Nitrogen digestibility(%) | F3: ME (MJ/kg) | G3: DE (%) | H3: ME (MJ/kg) - pigs | I3: Nitrogen digestibility(%) | J3: ME (MJ/kg) - poultry | K3: CP (%DM) | L3: source
A4: Pigeon pea (Cajanus cajan), aerial part, fresh | B4: 31.8 | C4: 19.7 | D4: 12.1 | E4: 64.5 | F4: 9.6 | K4: 19 | L4: https://www.feedipedia.org/node/11909
A5: Pigeon pea (Cajanus cajan), hay | B5: 90.3 | C5: 19.2 | D5: 10.8 | F5: 8.7 | K5: 14.5 | L5: https://www.feedipedia.org/node/11910
A7: mean | B7: =AVERAGE(B4,B5) -> 61.05 | C7: =AVERAGE(C4:C5) -> 19.45 | D7: =AVERAGE(D4:D5) -> 11.45 | F7: =AVERAGE(F4:F5) -> 9.15 | G7: =AVERAGE(G4:G5) -> #DIV/0! | H7: =AVERAGE(H4:H5) -> #DIV/0! | J7: =AVERAGE(J4:J5) -> #DIV/0! | K7: =AVERAGE(K4:K5) -> 16.75

Sheet Banana stems)
A1: BANANA STEMS
D2: ruminants | G2: monogastrics
A3: Name | B3: Dry matter (%) | C3: GE (MJ/kg) | D3: DE (MJ/kg) | E3: ME (MJ/kg) | F3: Nitrogen digestibility (%) | G3: DE (MJ/kg) - pigs | H3: ME (MJ/kg) - pigs | I3: ME (MJ/kg) - poultry | J3: CP (%DM) | K3: source
A4: Banana shoots, fresh | C4: 17.9 | G4: 2.6 | J4: 7.7 | K4: https://www.feedipedia.org/node/11816
A5: Plantain banana trunk, fresh | B5: 6.9 | C5: 16.7 | G5: 8.8 | J5: 3.5 | K5: https://www.feedipedia.org/node/12462
A6: Banana stalks, fresh | B6: 7.2 | C6: 16.6 | G6: 7.4 | J6: 5.1 | K6: https://www.feedipedia.org/node/11817
A7: Banana, aerial part, fresh | B7: 16 | C7: 17.7 | D7: 12.4 | E7: 9.9 | F7: 54.7 | J7: 16.6 | K7: https://www.feedipedia.org/node/11818
A8: Plantain banana shoots, fresh | C8: 17.1 | G8: 2.7 | J8: 8.7 | K8: https://www.feedipedia.org/node/12461
A10: mean | B10: =AVERAGE(B5,B6,B7) -> 10.033333 | C10: =AVERAGE(C4:C8) -> 17.2 | D10: =AVERAGE(D4:D8) -> 12.4 | E10: =AVERAGE(E4:E8) -> 9.9 | G10: =AVERAGE(G4:G8) -> 5.375 | H10: =AVERAGE(H4:H8) -> #DIV/0! | J10: =AVERAGE(J4:J8) -> 8.32

Sheet Mango
A1: MANGO
D2: ruminants | G2: monogastrics
A3: Name | B3: Dry matter (%) | C3: GE (MJ/kg) | D3: DE (MJ/kg) | E3: ME (MJ/kg) | F3: Nitrogen digestibility (%) | G3: DE (MJ/kg) - pigs | H3: ME (MJ/kg) - pigs | I3: ME (MJ/kg) - poultry | J3: CP (%DM) | K3: source
A4: Mango (Mangifera indica) fruits, fresh | B4: 17.1 | C4: 17.9 | J4: 4.7 | K4: https://www.feedipedia.org/node/12304
A5: Mango (Mangifera indica), pulp, fresh | B5: 17.5 | C5: 17.8 | G5: 14.1 | J5: 4.2 | K5: https://www.feedipedia.org/node/12308
A6: Mango (Mangifera indica), kernels, fresh | B6: 53.5 | C6: 18.9 | E6: 10.7 | F6: 72.1 | G6: 16.4 | J6: 6.4 | K6: https://www.feedipedia.org/node/12305
A7: Mango (Mangifera indica), kernels, dried | B7: 91.9 | C7: 20.2 | D7: 17.2 | J7: 7.5 | K7: https://www.feedipedia.org/node/12817
A8: Mango (Mangifera indica), peels, fresh | B8: 15.6 | C8: 17.7 | G8: 13.8 | J8: 6.2 | K8: https://www.feedipedia.org/node/12814
A9: Mango (Mangifera indica), peels, dried | B9: 92.2 | C9: 17.8 | G9: 12.5 | J9: 4.6 | K9: https://www.feedipedia.org/node/12815
A10: Mango (Mangifera indica), juice extraction by-product, dried | B10: 91.9 | C10: 18.6 | D10: 15.6 | E10: 13.1 | G10: 12.5 | J10: 5 | K10: https://www.feedipedia.org/node/14827
A11: Mango (Mangifera indica), oil meal | B11: 93.7 | C11: 17.4 | G11: 14.9 | J11: 6.9 | K11: https://www.feedipedia.org/node/12816
A13: mean | B13: =AVERAGE(B4,B5,B6,B7,B8,B9,B10,B11) -> 59.175 | C13: =AVERAGE(C4,C5,C6,C7,C8,C9,C10,C11) -> 18.2875 | D13: =AVERAGE(D7,D10) -> 16.4 | E13: =AVERAGE(E6,E10) -> 11.9 | G13: =AVERAGE(G5,G6,G8,G9,G10,G11) -> 14.033333 | H13: =AVERAGE(H4:H8) -> #DIV/0! | J13: =AVERAGE(J4,J5,J6,J7,J8,J9,J10,J11) -> 5.6875

Sheet Lemon Lime
A1: LEMON and LIME
D2: ruminants | G2: monogastrics
A3: Name | B3: Dry matter (%) | C3: GE (MJ/kg) | D3: DE (MJ/kg) | E3: ME (MJ/kg) | F3: Nitrogen digestibility (%) | G3: DE (MJ/kg) - pigs | H3: ME (MJ/kg) - pigs | I3: ME (MJ/kg) - poultry | J3: Nitrogen digestibility(%) | K3: CP (%DM) | L3: source
A4: Lime (Citrus aurantiifolia), fruits | B4: 31.9 | C4: 20.5 | G4: 4.9 | K4: 11.3 | L4: https://www.feedipedia.org/node/12257
A5: Lemon fruits, dried | B5: 92.1 | C5: 16.5 | D5: 12.3 | E5: 10.2 | F5: 63.4 | G5: 10.6 | J5: 41.4 | K5: 8.1 | L5: https://www.feedipedia.org/node/12847
A8: mean | B8: =AVERAGE(B4,B5) -> 62 | C8: =AVERAGE(C4,C5) -> 18.5 | G8: =AVERAGE(G4,G5) -> 7.75 | K8: =AVERAGE(K4,K5) -> 9.7

Sheet Carobs
A1: CAROBS
D2: ruminants | G2: monogastrics
A3: Name | B3: Dry matter (%) | C3: GE (MJ/kg) | D3: DE (MJ/kg) | E3: ME (MJ/kg) | F3: Nitrogen digestibility (%) | G3: DE (MJ/kg) - pigs | H3: ME (MJ/kg) - pigs | I3: ME (MJ/kg) - poultry | J3: Nitrogen digestibility(%) | K3: CP (%DM) | L3: source
A4: Carob (Ceratonia siliqua), pod meal, without seeds | B4: 85.3 | C4: 17.4 | D4: 10.3 | E4: 8.7 | F4: 26.1 | G4: 8.5 | H4: 8.2 | J4: 69.2 | K4: 5.1 | L4: https://www.feedipedia.org/node/11933
A5: Carob (Ceratonia siliqua), whole pods | B5: 83.2 | C5: 18 | E5: 11.2 | G5: 9.9 | J5: 71.9 | K5: 7.8 | L5: https://www.feedipedia.org/node/14532
A6: Carob (Ceratonia siliqua), germ, dehydrated | B6: 91.7 | C6: 20.7 | E6: 9.9 | G6: 17.3 | K6: 49.4 | L6: https://www.feedipedia.org/node/11932
A7: Carob (Ceratonia siliqua), seeds | C7: 18.8 | D7: 16.8 | E7: 13.7 | F7: 67 | G7: 14.1 | H7: 13.4 | K7: 17.8 | L7: https://www.feedipedia.org/node/11936
A9: mean | B9: =AVERAGE(B4,B5,B6) -> 86.733333 | C9: =AVERAGE(C4,C5,C6,C7) -> 18.725 | D9: =AVERAGE(D4,D7) -> 13.55 | E9: =AVERAGE(E4,E5,E6,E7) -> 10.875 | F9: =AVERAGE(F4,F7) -> 46.55 | G9: =AVERAGE(G4,G5,G6,G7) -> 12.45 | H9: =AVERAGE(H4,H7) -> 10.8 | J9: =AVERAGE(J4,J5) -> 70.55 | K9: =AVERAGE(K4,K5,K6,K7) -> 20.025

Sheet Castor oil
A1: CASTOR OIL
D2: ruminants | G2: monogastrics
A3: Name | B3: Dry matter (%) | C3: GE (MJ/kg) | D3: DE (MJ/kg) | E3: ME (MJ/kg) | F3: Nitrogen digestibility (%) | G3: DE (MJ/kg) - pigs | H3: ME (MJ/kg) - pigs | I3: ME (MJ/kg) - poultry | J3: Nitrogen digestibility(%) | K3: CP (%DM) | L3: source
A4: Castor (Ricinus communis), oil cake, detoxified, oil < 5% | B4: 89.6 | C4: 19.2 | D4: =C4*0.65 -> 12.48 | E4: 9.4 | F4: 76.6 | G4: 11.1 | H4: 10.3 | I4: =AVERAGE(7.8,8) -> 7.9 | J4: 45.6 | K4: 35.9 | L4: https://www.feedipedia.org/node/11950
A5: Castor (Ricinus communis), oil cake, detoxified, oil > 5% | B5: 89.8 | C5: 21.4 | D5: =0.66*C5 -> 14.124 | E5: 10.8 | F5: 75.6 | G5: 12.8 | H5: 12 | I5: =AVERAGE(10.9,10.4) -> 10.65 | J5: 61.1 | K5: 33.1 | L5: https://www.feedipedia.org/node/26844
A7: mean | B7: =AVERAGE(B4,B5) -> 89.7 | C7: =AVERAGE(C4,C5) -> 20.3 | D7: =AVERAGE(D4,D5) -> 13.302 | E7: =AVERAGE(E4,E5) -> 10.1 | F7: =AVERAGE(F4,F5) -> 76.1 | G7: =AVERAGE(G4,G5) -> 11.95 | H7: =AVERAGE(H4,H5) -> 11.15 | I7: =AVERAGE(I4,I5) -> 9.275 | ... K7: =AVERAGE(K4,K5) -> 34.5

Sheet Poppy oil meal
A1: POPPY OIL MEAL
D2: ruminants | G2: monogastrics
A3: Name | B3: Dry matter (%) | C3: GE (MJ/kg) | D3: DE (MJ/kg) | E3: ME (MJ/kg) | F3: Nitrogen digestibility (%) | G3: DE (MJ/kg) - pigs | H3: ME (MJ/kg) - pigs | I3: ME (MJ/kg) - poultry | J3: Nitrogen digestibility(%) | K3: CP (%DM) | L3: source
A4: Poppy (Papaver somniferum), oil meal, mechanical extraction | B4: 92.5 | C4: 19.9 | D4: 14.4 | E4: 11 | F4: 79.1 | G4: 12.7 | H4: 11.7 | K4: 19.9 | L4: https://www.feedipedia.org/node/12463
A5: Poppy (Papaver somniferum), oil meal, solvent extraction | B5: 89.8 | C5: 18.1 | G5: 10.9 | K5: 39.3 | L5: https://www.feedipedia.org/node/12464
A7: mean | B7: =AVERAGE(B4,B5) -> 91.15 | C7: =AVERAGE(C4,C5) -> 19 | D7: =AVERAGE(D4,D5) -> 14.4 | E7: =AVERAGE(E4,E5) -> 11 | F7: =AVERAGE(F4,F5) -> 79.1 | G7: =AVERAGE(G4,G5) -> 11.8 | H7: =AVERAGE(H4,H5) -> 11.7 | K7: =AVERAGE(K4,K5) -> 29.6

Sheet Orange
A2: ORANGE | D2: ruminants | G2: monogastrics
A3: Name | B3: Dry matter (%) | C3: GE (MJ/kg) | D3: DE (MJ/kg) | E3: ME (MJ/kg) | F3: Nitrogen digestibility (%) | G3: DE (MJ/kg) - pigs | H3: ME (MJ/kg) - pigs | I3: ME (MJ/kg) - poultry | J3: Nitrogen digestibility(%) | K3: CP (%DM) | L3: source
A4: Orange peels, fresh | B4: 16.1 | C4: 18.3 | D4: 17.3 | E4: 14.6 | F4: 76.8 | G4: 14.9 | J4: 74.2 | K4: 6.8 | L4: https://www.feedipedia.org/node/12415
A5: Orange peels, silage | B5: 19.6 | C5: 18.1 | D5: 15.1 | E5: 12.6 | F5: 67.7 | G5: 12.9 | J5: 61.1 | K5: 7.7 | L5: https://www.feedipedia.org/node/12416
A8: mean | B8: =AVERAGE(B4,B5) -> 17.85 | C8: =AVERAGE(C4,C5) -> 18.2 | D8: =AVERAGE(D4,D5) -> 16.2 | E8: =AVERAGE(E4,E5) -> 13.6 | F8: =AVERAGE(F4,F5) -> 72.25 | G8: =AVERAGE(G4,G5) -> 13.9 | J8: =AVERAGE(J4,J5) -> 67.65 | K8: =AVERAGE(K4,K5) -> 7.25

Sheet Grapes
A2: GRAPES | D2: ruminants | G2: monogastrics
A3: Name | B3: Dry matter (%) | C3: GE (MJ/kg) | D3: DE (MJ/kg) | E3: ME (MJ/kg) | F3: Nitrogen digestibility (%) | G3: DE (MJ/kg) - pigs | H3: ME (MJ/kg) - pigs | I3: ME (MJ/kg) - poultry | J3: Nitrogen digestibility(%) | K3: CP (%DM) | L3: source
A4: Grape leaves, fresh | B4: 34.6 | C4: 18 | D4: 7.7 | E4: 6.3 | F4: 17.5 | K4: 10.4 | L4: https://www.feedipedia.org/node/12132
A5: Grape branches and leaves, fresh | B5: 56.3 | C5: 18.5 | D5: 6.3 | E5: 5.1 | F5: -1.7 | K5: 4.6
A7: mean | B7: =AVERAGE(B4,B5) -> 45.45 | C7: =AVERAGE(C4,C5) -> 18.25 | D7: =AVERAGE(D4,D5) -> 7 | E7: =AVERAGE(E4,E5) -> 5.7 | F7: =AVERAGE(F4,F5) -> 7.9 | K7: =AVERAGE(K4,K5) -> 7.5

Sheet Papaya
A1: PAPAYA
D2: ruminants | G2: monogastrics
A3: Name | B3: Dry matter (%) | C3: GE (MJ/kg) | D3: DE (MJ/kg) | E3: ME (MJ/kg) | F3: Nitrogen digestibility (%) | G3: DE (MJ/kg) - pigs | H3: ME (MJ/kg) - pigs | I3: ME (MJ/kg) - poultry | J3: CP (%DM) | K3: source
A4: Papaya leaves, fresh | B4: 20.9 | C4: 18.4 | J4: 25.6 | K4: https://www.feedipedia.org/node/11551
A5: Papaya leaves, dried | B5: 92.5 | C5: 17.8 | J5: 23.5 | K5: https://www.feedipedia.org/node/11552
A6: Papaya peels, fresh | B6: 9.3 | C6: 17.4 | G6: 13.8 | J6: 9 | K6: https://www.feedipedia.org/node/11553
A7: Papaya pomace, dried | B7: 92.2 | C7: 17 | G7: 8.2 | J7: 18.2 | K7: https://www.feedipedia.org/node/11554
A8: Papaya fruit | B8: 8.2 | C8: 17.1 | G8: 12.2 | J8: 11.3 | K8: https://www.feedipedia.org/node/11550
A13: mean | B13: =AVERAGE(B4,B5,B6,B7,B8) -> 44.62 | C13: =AVERAGE(C4,C5,C6,C7,C8) -> 17.54 | G13: =AVERAGE(G6,G7,G8) -> 11.4 | J13: =AVERAGE(J4,J5,J6,J7,J8) -> 17.52

Sheet Olives residues
A1: OLIVE RESIDUES
D2: ruminants | G2: monogastrics
A3: Name | B3: Dry matter (%) | C3: GE (MJ/kg) | D3: DE (MJ/kg) | E3: ME (MJ/kg) | F3: Nitrogen digestibility (%) | G3: DE (MJ/kg) - pigs | H3: ME (MJ/kg) - pigs | I3: ME (MJ/kg) - poultry | J3: CP (%DM) | K3: source
A4: Olive leaves, silage | B4: 77.1 | C4: 19.2 | E4: 7.2 | F4: 16.8 | J4: 12.2 | K4: https://www.feedipedia.org/node/12408
A5: Olive leaves and branches, dry | B5: 89.8 | C5: 18.5 | D5: 5.5 | E5: 4.5 | F5: 22.2 | J5: 7.8 | K5: https://www.feedipedia.org/node/12406
A6: Olive leaves, fresh | B6: 50.1 | C6: 18.3 | D6: 9.8 | E6: 8.1 | F6: 44.3 | J6: 9.8 | K6: https://www.feedipedia.org/node/12407
A8: mean | B8: =AVERAGE(B4,B5,B6) -> 72.333333 | C8: =AVERAGE(C4,C5,C6) -> 18.666667 | D8: =AVERAGE(D4,D5,D6) -> 7.65 | E8: =AVERAGE(E4,E5,E6) -> 6.6 | F8: =AVERAGE(F4,F5,F6) -> 27.766667 | J8: =AVERAGE(J4,J5,J6) -> 9.9333333

Sheet Olive  oil cake
A1: OLIVE OIL CAKE
D2: ruminants | G2: monogastrics
A3: Name | B3: Dry matter (%) | C3: GE (MJ/kg) | D3: DE (MJ/kg) | E3: ME (MJ/kg) | F3: Nitrogen digestibility (%) | G3: DE (MJ/kg) - pigs | H3: ME (MJ/kg) - pigs | I3: ME (MJ/kg) - poultry | J3: CP (%DM) | K3: source
A4: Olive oil cake, crude, with stones | B4: 87.7 | C4: 20.8 | D4: 5.1 | E4: 4.1 | F4: 8.5 | G4: 6.3 | J4: 7.8 | K4: https://www.feedipedia.org/node/12409
A5: Olive oil cake, crude, without stones | B5: 87.5 | C5: 20.6 | D5: 7.7 | E5: 6.2 | G5: 9.2 | J5: 9.5 | K5: https://www.feedipedia.org/node/12886
A6: Olive oil cake, exhausted, with stones | B6: 88.4 | C6: 18.6 | D6: 4.4 | E6: 3.5 | F6: 24 | G6: 5.8 | J6: 12.7 | K6: https://www.feedipedia.org/node/12887
A7: Olive oil cake, exhausted, without stones | B7: 82.8 | C7: 18.8 | D7: 7.6 | E7: 6.2 | G7: 9.1 | J7: 11 | K7: https://www.feedipedia.org/node/12888
A9: mean | B9: =AVERAGE(B4,B5,B6,B7) -> 86.6 | C9: =AVERAGE(C4,C5,C6,C7) -> 19.7 | D9: =AVERAGE(D4,D5,D6,D7) -> 6.2 | E9: =AVERAGE(E4,E5,E6,E7) -> 5 | F9: =AVERAGE(F4,F5,F6,F7) -> 16.25 | G9: =AVERAGE(G4,G5,G6,G7) -> 7.6 | J9: =AVERAGE(J4,J5,J6,J7) -> 10.25

Sheet Palm kernels
A1: PALM KERNELS
D2: ruminants | G2: monogastrics
A3: Name | B3: Dry matter (%) | C3: GE (MJ/kg) | D3: DE (MJ/kg) | E3: ME (MJ/kg) | F3: Nitrogen digestibility (%) | G3: DE (MJ/kg) - pigs | H3: ME (MJ/kg) - pigs | I3: ME (MJ/kg) - poultry | J3: CP (%DM) | K3: source
A4: Babassu (Attalea speciosa), oil meal, partially decorticated, expeller extraction | B4: 92.2 | C4: 20.2 | G4: 8 | J4: 21.9 | K4: https://www.feedipedia.org/node/11792
A5: Babassu (Attalea speciosa), oil meal, partially decorticated, solvent extraction | B5: 91.6 | C5: 19.1 | G5: 8.3 | J5: 18.7 | K5: https://www.feedipedia.org/node/12823
A6: Babassu (Attalea speciosa), oil meal, decorticated, expeller extraction | B6: 91.5 | C6: 19.9 | D6: =0.68*C6 -> 13.532 | E6: 11.5 | F6: 85 | G6: 12.8 | J6: 25.1 | K6: https://www.feedipedia.org/node/12824
A7: Babassu (Attalea speciosa), oil meal, decorticated, solvent extraction | B7: 91.4 | C7: 18.6 | G7: 11.5 | J7: 24.1 | K7: https://www.feedipedia.org/node/12825
A9: mean | B9: =AVERAGE(B4,B5,B7,B6) -> 91.675 | C9: =AVERAGE(C4,C5,C7,C6) -> 19.45 | D9: =AVERAGE(D4,D5,D7,D6) -> 13.532 | E9: =AVERAGE(E4,E5,E7,E6) -> 11.5 | F9: =AVERAGE(F4,F5,F7,F6) -> 85 | G9: =AVERAGE(G4,G5,G7,G6) -> 10.15 | J9: =AVERAGE(J4,J5,J7,J6) -> 22.45

Sheet Yams
A1: YAMS
D2: ruminants | G2: monogastrics
A3: Name | B3: Dry matter (%) | C3: GE (MJ/kg) | D3: DE (MJ/kg) | E3: ME (MJ/kg) | F3: Nitrogen digestibility (%) | G3: DE (MJ/kg) - pigs | H3: ME (MJ/kg) - pigs | I3: ME (MJ/kg) - poultry | J3: CP (%DM) | K3: source
A4: White yam (Dioscorea rotundata), tuber, fresh | B4: 26.2 | C4: 17.1 | G4: 14.8 | J4: 5.9 | K4: https://www.feedipedia.org/node/12767
A5: Chinese yam (Dioscorea esculenta), tuber, fresh | B5: 18.6 | C5: 17.3 | G5: 14.7 | J5: 8.7 | K5: https://www.feedipedia.org/node/11980
A6: Yellow yam (Dioscorea cayenensis), tuber, fresh | B6: 16.6 | C6: 17.3 | G6: 14.9 | J6: 6.2 | K6: https://www.feedipedia.org/node/12795
A7: Winged yam (Dioscorea alata), tuber, fresh | B7: 29.8 | C7: 17.2 | G7: 14.8 | J7: 8.9 | K7: https://www.feedipedia.org/node/12778
A9: mean | B9: =AVERAGE(B4,B5,B6,B7) -> 22.8 | C9: =AVERAGE(C4,C5,C6,C7) -> 17.225 | G9: =AVERAGE(G4,G5,G6,G7) -> 14.8 | J9: =AVERAGE(J4,J5,J6,J7) -> 7.425

Sheet Taro
A1: TARO
D2: ruminants | G2: monogastrics
A3: Name | B3: Dry matter (%) | C3: GE (MJ/kg) | D3: DE (MJ/kg) | E3: ME (MJ/kg) | F3: Nitrogen digestibility (%) | G3: DE (MJ/kg) - pigs | H3: ME (MJ/kg) - pigs | I3: ME (MJ/kg) - poultry | J3: CP (%DM) | K3: source
A4: Taro (Colocasia esculenta), tuber, fresh | B4: 28.6 | C4: 17.2 | G4: 14.8 | H4: 14.5 | J4: 5.4 | K4: https://www.feedipedia.org/node/12692
A5: Taro (Colocasia esculenta), tuber, peeled, fresh | B5: 31.9 | C5: 17.2 | G5: 14.7 | J5: 6.9 | K5: https://www.feedipedia.org/node/12693
A6: Taro (Colocasia esculenta), tuber, dried | B6: 89.5 | C6: 17.3 | D6: 14.1 | E6: 11.8 | F6: 62.7 | G6: 15 | I6: =AVERAGE(11.7,10.8) -> 11.25 | J6: 8.1 | K6: https://www.feedipedia.org/node/17276
A8: mean | B8: =AVERAGE(B5,B4,B6) -> 50 | C8: =AVERAGE(C5,C4,C6) -> 17.233333 | D8: =AVERAGE(D5,D4,D6) -> 14.1 | E8: =AVERAGE(E5,E4,E6) -> 11.8 | F8: =AVERAGE(F5,F4,F6) -> 62.7 | G8: =AVERAGE(G5,G4,G6) -> 14.833333 | H8: =AVERAGE(H5,H4,H6) -> 14.5 | I8: =AVERAGE(I5,I4,I6) -> 11.25 | J8: =AVERAGE(J5,J4,J6) -> 6.8

Sheet Yautia
A1: TARO
D2: ruminants | G2: monogastrics
A3: Name | B3: Dry matter (%) | C3: GE (MJ/kg) | D3: DE (MJ/kg) | E3: ME (MJ/kg) | F3: Nitrogen digestibility (%) | G3: DE (MJ/kg) - pigs | H3: ME (MJ/kg) - pigs | I3: ME (MJ/kg) - poultry | J3: CP (%DM) | K3: source
A4: Malanga (Xanthosoma sagittifolium), peelings, fresh | B4: 29.5 | C4: 17 | G4: 12.3 | J4: 8.2 | K4: https://www.feedipedia.org/node/12300
A5: Malanga (Xanthosoma sagittifolium), tubers, fresh | B5: 31 | C5: 17.1 | G5: 14.7 | J5: 6.8 | K5: https://www.feedipedia.org/node/12302
A6: Malanga (Xanthosoma sagittifolium), tubers, peeled, fresh | B6: 24.1 | C6: 16.8 | G6: 14.8 | J6: 5.9 | K6: https://www.feedipedia.org/node/12303
A8: mean | B8: =AVERAGE(B4,B5,B6) -> 28.2 | C8: =AVERAGE(C4,C5,C6) -> 16.966667 | G8: =AVERAGE(G4,G5,G6) -> 13.933333 | J8: =AVERAGE(J4,J5,J6) -> 6.9666667

Sheet Lupins)
A1: LUPINS
D2: ruminants | G2: monogastrics
A3: Name | B3: Dry matter (%) | C3: GE (MJ/kg) | D3: DE (MJ/kg) | E3: ME (MJ/kg) | F3: Nitrogen digestibility (%) | G3: DE (MJ/kg) | H3: ME (MJ/kg) - pigs | I3: ME (MJ/kg) - poultry | J3: Nitrogen digestibility (%) | K3: CP (%DM) | L3: source
A4: Blue lupin (Lupinus angustifolius) seeds | B4: 90.2 | C4: 20.3 | D4: =C4*0.89 -> 18.067 | E4: 14.1 | F4: 80 | G4: 15.8 | H4: 14.7 | J4: 84 | K4: 33.7 | L4: https://www.feedipedia.org/node/12271
A5: White lupin (Lupinus albus), seeds | B5: 88.1 | C5: 21.2 | D5: =C5*0.906 -> 19.2072 | E5: 14.8 | F5: 79.9 | G5: 17 | H5: 15.8 | I5: =AVERAGE(11.4,11.1) -> 11.25 | J5: 82.8 | K5: 37.9 | L5: https://www.feedipedia.org/node/12275
A6: Yellow lupin (Lupinus luteus) seeds | B6: 88.8 | C6: 20.5 | D6: =C6*0.89 -> 18.245 | E6: 13.9 | F6: 80 | G6: 15.6 | H6: 14.4 | J6: 83 | K6: 42.2 | L6: https://www.feedipedia.org/node/23097
A8: mean | B8: =AVERAGE(B4:B6) -> 89.033333 | C8: =AVERAGE(C4:C6) -> 20.666667 | D8: =AVERAGE(D4:D6) -> 18.5064 | E8: =AVERAGE(E4:E6) -> 14.266667 | F8: =AVERAGE(F4:F6) -> 79.966667 | G8: =AVERAGE(G4:G6) -> 16.133333 | H8: =AVERAGE(H4:H6) -> 14.966667 | I8: =AVERAGE(I4:I6) -> 11.25 | ... K8: =AVERAGE(K4:K6) -> 37.933333

Sheet Cereal straws
A1: CEREAL STRAWS
D2: ruminants | G2: monogastrics
A3: Name | B3: Dry matter (%) | C3: GE (MJ/kg) | D3: DE (MJ/kg) | E3: ME (MJ/kg) | F3: Nitrogen digestibility (%) | G3: DE (MJ/kg) - pigs | H3: ME (MJ/kg) - pigs | I3: ME (MJ/kg) - poultry | J3: Nitrogen digestibility% | K3: CP (%DM) | L3: source | M3: source2
A4: Wheat straw | B4: 91 | C4: 18.5 | D4: 8.3 | E4: 6.8 | F4: 3.5 | G4: 2.3 | H4: 2 | I4: 2.1 | J4: 45.7 | K4: 4.2 | L4: https://www.feedipedia.org/node/12758 | M4: https://www.feedtables.com/content/wheat-straw
A5: Barley straw | B5: 90.9 | C5: 18.2 | D5: 8 | E5: 6.5 | F5: 30.3 | G5: 2.5 | H5: 2.2 | K5: 3.8 | L5: https://www.feedipedia.org/node/11830
A6: Oat straw | B6: 89.6 | C6: 18 | D6: 8.1 | E6: 6.6 | F6: 31 | G6: 2.7 | H6: 2.4 | I6: =AVERAGE(4.3,3.9) -> 4.1 | J6: 76.2 | K6: 3.6 | L6: https://www.feedipedia.org/node/12389 | M6: https://www.feedtables.com/content/oat-hulls
A7: Triticale straw | B7: 92.5 | C7: 18.7 | D7: 8.8 | E7: 7.2 | G7: 3 | H7: 2.7 | K7: 3.2 | L7: https://www.feedipedia.org/node/16332
A8: Rye straw | B8: 92 | C8: 18.3 | D8: 8.2 | E8: 6.6 | F8: 2 | G8: 2.2 | H8: 1.9 | K8: 4.1 | L8: https://www.feedipedia.org/node/14205
A9: Tef (Eragrostif tef), aerial part, straw | B9: 91.6 | C9: 18.1 | D9: 9.7 | E9: 7.9 | F9: 15.6 | K9: 4.1 | L9: https://www.feedipedia.org/node/22526
A11: mean | B11: =AVERAGE(B4,B5,B6,B7,B8,B9) -> 91.266667 | C11: =AVERAGE(C4,C5,C6,C7,C8,C9) -> 18.3 | D11: =AVERAGE(D4,D5,D6,D7,D8,D9) -> 8.5166667 | E11: =AVERAGE(E4,E5,E6,E7,E8,E9) -> 6.9333333 | F11: =AVERAGE(F4,F5,F6,F7,F8,F9) -> 16.48 | G11: =AVERAGE(G4,G5,G6,G7,G8,G9) -> 2.54 | H11: =AVERAGE(H4,H5,H6,H7,H8,H9) -> 2.24 | I11: =AVERAGE(I4,I5,I6,I7,I8,I9) -> 3.1 | ... K11: =AVERAGE(K4,K5,K6,K7,K8,K9) -> 3.8333333

Sheet Clover forage
A1: CLOVER FORAGE
D2: ruminants | G2: monogastrics
A3: Name | B3: Dry matter (%) | C3: GE (MJ/kg) | D3: DE (MJ/kg) | E3: ME (MJ/kg) | F3: Nitrogen digestibility (%) | G3: DE (MJ/kg) - pigs | H3: ME (MJ/kg) - pigs | I3: ME (MJ/kg) - poultry | J3: Nitrogen digestibility% | K3: CP (%DM) | L3: source
A4: White clover (Trifolium repens), aerial part, fresh | B4: 16.8 | C4: 18.3 | D4: 14.2 | E4: 11.1 | F4: 82.2 | K4: 24.9 | L4: https://www.feedipedia.org/node/12762
A5: Berseem (Trifolium alexandrinum), aerial part, fresh | B5: 12.5 | C5: 17.4 | D5: 12.2 | E5: 9.6 | F5: 74.9 | K5: 19.9 | L5: https://www.feedipedia.org/node/11851
A6: Crimson clover (Trifolium incarnatum), aerial part, fresh | B6: 25.2 | C6: 18.1 | D6: 13.1 | E6: 10.6 | F6: 74.1 | K6: 15.9 | L6: https://www.feedipedia.org/node/12035
A7: Persian clover (Trifolium resupinatum), aerial part, fresh | B7: 11.6 | C7: 17.6 | D7: 12.9 | E7: 10.3 | F7: 78.8 | K7: 21.6 | L7: https://www.feedipedia.org/node/12450
A8: Red clover (Trifolium pratense), aerial part, fresh | B8: 19 | C8: 18.4 | D8: 13.1 | E8: 10.4 | F8: 73.3 | K8: 19.7 | L8: https://www.feedipedia.org/node/12508
A9: Subterranean clover (Trifolium subterraneum), aerial part, fresh | B9: 15.1 | C9: 18.3 | D9: 12 | E9: 9.5 | F9: 77 | K9: 18.1 | L9: https://www.feedipedia.org/node/12645
A10: Tembien clover (Trifolium tembense), aerial part, fresh | B10: 19.9 | C10: 18.3 | D10: 13.6 | E10: 10.9 | K10: 17.8 | L10: https://www.feedipedia.org/node/12696
A12: mean | B12: =AVERAGE(B4,B5,B6,B7,B8,B9,B10) -> 17.157143 | C12: =AVERAGE(C4,C5,C6,C7,C8,C9,C10) -> 18.057143 | D12: =AVERAGE(D4,D5,D6,D7,D8,D9,D10) -> 13.014286 | E12: =AVERAGE(E4,E5,E6,E7,E8,E9,E10) -> 10.342857 | F12: =AVERAGE(F4,F5,F6,F7,F8,F9,F10) -> 76.716667 | K12: =AVERAGE(K4,K5,K6,K7,K8,K9,K10) -> 19.7

Sheet Hay grass non leguminose
A1: HAY GRASS NON-LEGUMINOSE
D2: ruminants | G2: monogastrics
A3: Name | B3: Dry matter (%) | C3: GE (MJ/kg) | D3: DE (MJ/kg) | E3: ME (MJ/kg) | F3: Nitrogen digestibility (%) | G3: DE (MJ/kg) - pigs | H3: ME (MJ/kg) - pigs | I3: ME (MJ/kg) - poultry | J3: Nitrogen digestibility% | K3: CP (%DM) | L3: source
A4: Elephant grass (Pennisetum purpureum), hay | B4: 89.3 | C4: 17.9 | D4: 9.9 | E4: 7.9 | F4: 59.4 | K4: 10.3 | L4: https://www.feedipedia.org/node/12366
A5: Dubi grass (Urochloa oligotricha), hay | B5: 89.3 | C5: 17.6 | D5: 12 | E5: 9.6 | F5: 37.6 | K5: 17.7 | L5: https://www.feedipedia.org/node/12062
A6: Dal grass (Hymenachne amplexicaulis), hay | C6: 17 | D6: 10.4 | E6: 8.5 | F6: 42.4 | K6: 7.5 | L6: https://www.feedipedia.org/node/12045
A7: Bermuda grass (Cynodon dactylon), hay | B7: 91.5 | C7: 18.3 | D7: 9.2 | E7: 7.4 | F7: 58.3 | K7: 10.2 | L7: https://www.feedipedia.org/node/11850
A8: Nile grass (Acroceras macrum), aerial part, hay | C8: 18.5 | D8: 10.9 | E8: 8.8 | F8: 57.5 | K8: 8.5 | L8: https://www.feedipedia.org/node/12382
A9: Congo grass (Brachiaria ruziziensis), hay | B9: 89.5 | C9: 18 | D9: 7.9 | E9: 6.4 | K9: 4.6 | L9: https://www.feedipedia.org/node/12848
A10: St Augustine grass (Stenotaphrum secundatum), hay | C10: 19.1 | D10: 11 | E10: 9 | F10: 30.7 | K10: 6.7 | L10: https://www.feedipedia.org/node/12640
B11: =AVERAGE(B4,B5,B7,B9) -> 89.9 | C11: =AVERAGE(C4,C6,C5,C7,C8,C9,C10) -> 18.057143 | D11: =AVERAGE(D4,D6,D5,D7,D8,D9,D10) -> 10.185714 | E11: =AVERAGE(E4,E6,E5,E7,E8,E9,E10) -> 8.2285714 | F11: =AVERAGE(F4,F6,F5,F7,F8,F9,F10) -> 47.65 | K11: =AVERAGE(K4,K6,K5,K7,K8,K9,K10) -> 9.3571429
A12: mean

Sheet Hay grass leguminose
A1: HAY GRASS LEGUMINOSE
D2: ruminants | G2: monogastrics
A3: Name | B3: Dry matter (%) | C3: GE (MJ/kg) | D3: DE (MJ/kg) | E3: ME (MJ/kg) | F3: Nitrogen digestibility (%) | G3: DE (MJ/kg) - pigs | H3: ME (MJ/kg) - pigs | I3: ME (MJ/kg) - poultry | J3: Nitrogen digestibility% | K3: CP (%DM) | L3: source
A4: Siratro (Macroptilium atropurpureum), aerial part, hay | B4: 85.9 | C4: 18.1 | D4: 9.1 | E4: 7.2 | F4: 80.9 | K4: 15.8 | L4: https://www.feedipedia.org/node/15457
A5: Velvet bean (Mucuna pruriens), hay | B5: 90.6 | C5: 18.5 | D5: 10.6 | E5: 8.5 | F5: 63.9 | K5: 14.8 | L5: https://www.feedipedia.org/node/12716
A6: Common vetch (Vicia sativa), hay | B6: 90.1 | C6: 18.1 | D6: 11 | E6: 8.7 | F6: 76.7 | K6: 19.7 | L6: https://www.feedipedia.org/node/12013
A7: Cowpea (Vigna unguiculata), hay | B7: 91.2 | C7: 17.5 | D7: 9.9 | E7: 7.8 | F7: 64.1 | K7: 14.8 | L7: https://www.feedipedia.org/node/12026
A8: Soybean hay | B8: 91.5 | C8: 19.6 | D8: 10.9 | E8: 8.6 | F8: 83.1 | K8: 15.9 | L8: https://www.feedipedia.org/node/12622
A10: mean | B10: =AVERAGE(B4,B5,B6,B7,B8) -> 89.86 | C10: =AVERAGE(C4,C5,C6,C7,C8) -> 18.36 | D10: =AVERAGE(D4,D5,D6,D7,D8) -> 10.3 | E10: =AVERAGE(E4,E5,E6,E7,E8) -> 8.16 | F10: =AVERAGE(F4,F5,F6,F7,F8) -> 73.74 | K10: =AVERAGE(K4,K5,K6,K7,K8) -> 16.2

Sheet Other grass
A1: OTHER GRASS
D3: ruminants | G3: monogastrics
A4: Name | B4: Dry matter (%) | C4: GE (MJ/kg) | D4: DE (MJ/kg) | E4: ME (MJ/kg) | F4: Nitrogen digestibility (%) | G4: DE (MJ/kg) - pigs | H4: ME (MJ/kg) - pigs | I4: ME (MJ/kg) - poultry | J4: Nitrogen digestibility% | K4: CP (%DM) | L4: source
A5: Whorled dropseed, fresh | B5: 41.4 | C5: 18 | D5: 11 | E5: 8.9 | G5: 6.9 | K5: 7.6 | L5: https://www.feedipedia.org/node/11536
A6: Columbus grass (Sorghum x almum), aerial part, fresh | B6: 17.5 | C6: 17.8 | D6: 10.8 | E6: 8.7 | F6: 33 | K6: 10 | L6: https://www.feedipedia.org/node/12004
A7: Elephant grass (Pennisetum purpureum), aerial part, fresh | B7: 17.9 | C7: 17.4 | D7: 10.2 | E7: 8.2 | F7: 57.3 | K7: 9.7 | L7: https://www.feedipedia.org/node/12365
A8: Cocksfoot, aerial part, fresh | B8: 20.7 | C8: 18 | D8: 12 | E8: 9.5 | F8: 58.9 | K8: 16.3 | L8: https://www.feedipedia.org/node/11991
A9: Rhodes grass (Chloris gayana), aerial part, fresh | B9: 24.9 | C9: 18.3 | D9: 10.6 | E9: 8.5 | F9: 65.3 | K9: 9 | L9: https://www.feedipedia.org/node/12518
A10: Sudan grass, fresh | B10: 20.8 | C10: 18.2 | D10: 11.6 | E10: 9.3 | F10: 68.2 | K10: 11 | L10: https://www.feedipedia.org/node/11534
A11: Timothy (Phleum pratense), aerial part, fresh | B11: 27 | C11: 18.2 | D11: 11.6 | E11: 9.3 | F11: 68 | K11: 13.8 | L11: https://www.feedipedia.org/node/16887
A13: mean | B13: =AVERAGE(B5,B6,B7,B8,B9,B10,B11) -> 24.314286 | C13: =AVERAGE(C5,C6,C7,C8,C9,C10,C11) -> 17.985714 | D13: =AVERAGE(D5,D6,D7,D8,D9,D10,D11) -> 11.114286 | E13: =AVERAGE(E5,E6,E7,E8,E9,E10,E11) -> 8.9142857 | F13: =AVERAGE(F5,F6,F7,F8,F9,F10,F11) -> 58.45 | K13: =AVERAGE(K5,K6,K7,K8,K9,K10,K11) -> 11.057143

Sheet Other legumes
A1: OTHER LEGUMES
D3: ruminants | G3: monogastrics
A4: Name | B4: Dry matter (%) | C4: GE (MJ/kg) | D4: DE (MJ/kg) | E4: ME (MJ/kg) | F4: Nitrogen digestibility (%) | G4: DE (MJ/kg) - pigs | H4: ME (MJ/kg) - pigs | I4: ME (MJ/kg) - poultry | J4: Nitrogen digestibility% | K4: CP (%DM) | L4: source
A5: Birdsfoot trefoil (Lotus corniculatus), aerial part, fresh | B5: 23.1 | C5: 18.9 | D5: 12.5 | E5: 9.8 | F5: 47.9 | K5: 21.1 | L5: https://www.feedipedia.org/node/11855
A6: Sericea (Lespedeza cuneata), aerial part, fresh | B6: 25 | C6: 17.7 | D6: 10.7 | E6: 8.5 | K6: 14.8 | L6: https://www.feedipedia.org/node/12574
A7: Kudzu, aerial part, fresh | B7: 26.5 | C7: 18.5 | D7: 11 | E7: 8.7 | F7: 85 | K7: 15.1 | L7: https://www.feedipedia.org/node/11546
A8: Agati (Sesbania grandiflora), aerial part, fresh | B8: 17.3 | C8: 19.2 | D8: 14.5 | E8: 11.5 | F8: 74 | K8: 25.5 | L8: https://www.feedipedia.org/node/11734
A9: Sesban (Sesbania sesban), aerial part, fresh | B9: 26 | C9: 18.3 | D9: 14.4 | E9: 11.5 | F9: 71.3 | K9: 24.4 | L9: https://www.feedipedia.org/node/12582
A10: Prickly sesban (Sesbania bispinosa), aerial part, fresh | B10: 21.2 | C10: 18.7 | D10: 13.5 | E10: 10.6 | F10: 63.7 | K10: 23.8 | L10: https://www.feedipedia.org/node/26497
A11: Sainfoin, aerial part, fresh | B11: 22.3 | C11: 19 | D11: 12.6 | E11: 10.1 | F11: 68.8 | K11: 16.9 | L11: https://www.feedipedia.org/node/11623
A12: Sulla (Hedysarum coronarium), aerial part, fresh | B12: 12.3 | C12: 18.1 | D12: 12.3 | E12: 9.7 | F12: 68.5 | K12: 20.2 | L12: https://www.feedipedia.org/node/12655
A14: mean | B14: =AVERAGE(B5,B6,B8,B7,B9,B10,B11,B12) -> 21.7125 | C14: =AVERAGE(C5,C6,C8,C7,C9,C10,C11,C12) -> 18.55 | D14: =AVERAGE(D5,D6,D8,D7,D9,D10,D11,D12) -> 12.6875 | E14: =AVERAGE(E5,E6,E8,E7,E9,E10,E11,E12) -> 10.05 | F14: =AVERAGE(F5,F6,F8,F7,F9,F10,F11,F12) -> 68.457143 | K14: =AVERAGE(K5,K6,K8,K7,K9,K10,K11,K12) -> 20.225

Sheet Maize)
A1: 19) MAIZE GRAIN
E2: ruminants | I2: monogastric
A3: Name | B3: Dry metter digestibility (%) | C3: GE (MJ/kg) | D3: CP (%DM) | E3: DE (MJ/kg) | F3: ME (MJ/kg) | G3: DE (MJ/kg) | H3: Nitrogen digestibility(%) | I3: ME (MJ/kg) - pigs | J3: ME (MJ/kg) - poultry | K3: Nitrogen digestibility(%) | L3: source
A4: maize grain europe | B4: 86.3 | C4: 18.7 | D4: 9.4 | E4: 16.1 | F4: 13.6 | G4: 16.5 | H4: 66.3 | I4: 16.1 | J4: 15.25 | K4: 80.8 | L4: http://www.feedipedia.org/node/556
A5: maize grain north africa and middle east | B5: 86.2 | C5: 18.7 | D5: 8.8 | E5: 16 | F5: 13.5 | G5: 16.2 | H5: 65.3 | I5: 15.9 | K5: 79.9 | L5: http://www.feedipedia.org/node/556
A6: maize grain subsaharan and east africa | B6: 90 | C6: 18.8 | D6: 8 | E6: 16.1 | F6: 13.6 | G6: 16.6 | H6: 64.2 | I6: 16.2 | J6: =AVERAGE(15.2,14.8) -> 15 | K6: 79.7 | L6: http://www.feedipedia.org/node/556
A7: maize grain north america | B7: 87.2 | C7: 18.7 | D7: 9.5 | E7: 16.2 | F7: 13.7 | G7: 16.5 | H7: 67 | I7: 16.1 | J7: 15.25 | K7: 81.4 | L7: http://www.feedipedia.org/node/556
A8: maize grain central and south america | B8: 86.7 | C8: 18.7 | D8: 9.2 | E8: 16.1 | F8: 13.6 | G8: 16.5 | H8: 65.8 | I8: 16.1 | K8: 80.3 | L8: http://www.feedipedia.org/node/556
A9: maize grain asia and asustralasia | B9: 87.2 | C9: 18.7 | D9: 9.7 | E9: 16.1 | F9: 13.5 | G9: 16.2 | H9: 67.1 | I9: 15.8 | J9: =AVERAGE(15.2,14.9) -> 15.05 | K9: 80.2 | L9: http://www.feedipedia.org/node/556
A11: mean | B11: =AVERAGE(B4,B5,B6,B7,B8,B9) -> 87.266667 | C11: =AVERAGE(C4:C9) -> 18.716667 | D11: =AVERAGE(D4:D9) -> 9.1 | E11: =AVERAGE(E4:E9) -> 16.1 | F11: =AVERAGE(F4:F9) -> 13.583333 | G11: =AVERAGE(G4:G9) -> 16.416667 | H11: =AVERAGE(H4,H5,H7,H6,H8,H9) -> 65.95 | I11: =AVERAGE(I4:I9) -> 16.033333 | J11: =AVERAGE(J4:J9) -> 15.1375 | K11: =AVERAGE(K4,K5,K6,K7,K8,K9) -> 80.383333

Sheet MIllet)
A1: MILLET
C2: ruminants | G2: monogastrics
A3: Name | B3: Dry metter content (%) | C3: GE (MJ/kg) | D3: DE (MJ/kg) | E3: ME (MJ/kg) | F3: Nitrogen digestibility(%) | G3: DE (%) | H3: ME (MJ/kg) - pigs | I3: ME (MJ/kg) - poultry | J3: Nitrogen digestibility(%) | K3: CP (%DM) | L3: source
A4: Finger millet | B4: 89 | C4: 17.7 | D4: 14 | E4: 11.8 | G4: 14.4 | K4: 8.9 | L4: https://www.feedipedia.org/node/721
A5: Pearl millet | B5: 89.6 | C5: 19.1 | D5: =C5*0.833 -> 15.9103 | E5: 13.3 | F5: 68.7 | G5: 14.2 | H5: 13.8 | I5: 13.2 | J5: 74.4 | K5: 12.5 | L5: https://www.feedipedia.org/node/724
A6: Foxtail millet | B6: 90.2 | C6: 18.8 | G6: 14.3 | H6: 13.8 | I6: 14.3 | K6: 11.9 | L6: https://www.feedipedia.org/node/725
A7: Proso millet | B7: 90.6 | C7: 19.3 | D7: =C7*0.805 -> 15.5365 | E7: 12.8 | F7: 70.4 | G7: 14.9 | H7: 14.5 | I7: =AVERAGE(15.7,15.3) -> 15.5 | J7: 78.6 | K7: 14.2 | L7: https://www.feedipedia.org/node/722
A9: mean | B9: =AVERAGE(B4,B5,B6,B7) -> 89.85 | C9: =AVERAGE(C4:C7) -> 18.725 | D9: =AVERAGE(D4:D7) -> 15.148933 | E9: =AVERAGE(E4:E7) -> 12.633333 | G9: =AVERAGE(G4:G7) -> 14.45 | H9: =AVERAGE(H4:H7) -> 14.033333 | I9: =AVERAGE(I4:I7) -> 14.333333 | J9: =AVERAGE(J5,J7) -> 76.5 | K9: =AVERAGE(K4:K7) -> 11.875

Sheet Soybean meal)
A1: SOYBEAN MEAL
D2: ruminants | G2: monogastrics
A3: Name | B3: Dry matter (%) | C3: GE (MJ/kg) | D3: DE (MJ/kg) | E3: ME (MJ/kg) | F3: Nitrogen digestibility(%) | G3: DE (%) | H3: ME (MJ/kg) - pigs | I3: ME (MJ/kg) - poultry | J3: Nitrogen digestibility(%) | K3: CP (%DM) | L3: source
A4: Type 50 | B4: 88 | C4: 19.7 | D4: =C4*0.916 -> 18.0452 | E4: 13.4 | F4: 80.2 | G4: 17.3 | H4: 15.8 | I4: 11.3 | J4: 90.1 | K4: 55.2 | L4: https://www.feedipedia.org/node/11683
